<?xml version="1.0" encoding="UTF-8"?>
<robot name="darwinOP">
  <material name="black">
    <color rgba="0.01 0.01 0.01 1.0"/>
  </material>
  <material name="lightgrey">
    <color rgba="0.40 0.40 0.40 1.0"/>
  </material>
  <link name="base_link"/>
  <joint name="base_link_to_body" type="fixed">
    <parent link="base_link"/>
    <child link="MP_BODY"/>
  </joint>
  <link name="MP_BODY">
    <inertial>
      <origin xyz="-0.01968089 -1.96e-06 -0.03183524"/>
      <mass value="0.97559947"/>
      <inertia ixx="0.00204518" ixy="6e-08" ixz="0.00021261" iyy="0.00176434" iyz="3.4e-07" izz="0.00196178"/>
    </inertial>
    <visual>
      <origin xyz="0 0 0" rpy="0 0 0"/>
      <geometry>
        <mesh filename="package://darwin_description/meshes/body.STL" scale="1 1 1"/>
      </geometry>
      <material name="Grey">
        <color rgba="0.20 0.20 0.20 1.0"/>
      </material>
    </visual>
    <collision>
      <geometry>
        <mesh filename="package://darwin_description/meshes/body_coll.stl" scale="1 1 1"/>
      </geometry>
    </collision>
  </link>
  <link name="MP_NECK">
    <inertial>
      <origin xyz="-3.2e-07 0.00065035 0.01592837"/>
      <mass value="0.02435772"/>
      <inertia ixx="3.22e-06" ixy="-0.0" ixz="0.0" iyy="6.2e-06" iyz="9e-08" izz="5.18e-06"/>
    </inertial>
    <visual>
      <origin xyz="0 0 0" rpy="0 0 0"/>
      <geometry>
        <mesh filename="package://darwin_description/meshes/neck.STL" scale="1 1 1"/>
      </geometry>
      <material name="lightgrey"/>
    </visual>
    <collision>
      <geometry>
        <mesh filename="package://darwin_description/meshes/neck_coll.stl" scale="1 1 1"/>
      </geometry>
    </collision>
  </link>
  <link name="MP_HEAD">
    <inertial>
      <origin xyz="0.0 -0.0244761 6.7e-07"/>
      <mass value="0.15804192"/>
      <inertia ixx="0.00012751" ixy="-0.0" ixz="0.0" iyy="0.00012751" iyz="-0.0" izz="0.00012734"/>
    </inertial>
    <visual>
      <origin xyz="0 0 0" rpy="0 0 0"/>
      <geometry>
        <mesh filename="package://darwin_description/meshes/head.STL" scale="1 1 1"/>
      </geometry>
      <material name="Grey">
        <color rgba="0.20 0.20 0.20 1.0"/>
      </material>
    </visual>
    <collision>
      <geometry>
        <mesh filename="package://darwin_description/meshes/head_coll_simple.stl" scale="1 1 1"/>
      </geometry>
    </collision>
  </link>
  <link name="MP_BACK_L">
    <inertial>
      <origin xyz="0.0 0.0 0.0"/>
      <mass value="0.01"/>
      <inertia ixx="0.0" ixy="0.0" ixz="0.0" iyy="0.0" iyz="0.0" izz="0.0"/>
    </inertial>
    <visual>
      <origin xyz="0.0 0.0 0.0" rpy="0 0 0"/>
      <geometry>
        <box size="0.001 0.001 0.001" scale="1 1 1"/>
      </geometry>
      <material name="Grey">
        <color rgba="0.20 0.20 0.20 1.0"/>
      </material>
    </visual>
    <collision>
      <geometry>
        <box size="0.001 0.001 0.001" scale="1 1 1"/>
      </geometry>
    </collision>
  </link>
  <link name="MP_SHOULDER_L">
    <inertial>
      <origin xyz="-0.00578109 2.23e-06 0.01384056"/>
      <mass value="0.02591302"/>
      <inertia ixx="6.01e-06" ixy="-0.0" ixz="7.3e-07" iyy="3.72e-06" iyz="0.0" izz="6.37e-06"/>
    </inertial>
    <visual>
      <origin xyz="0 0 0" rpy="0 0 0"/>
      <geometry>
        <mesh filename="package://darwin_description/meshes/shoulder_l.STL" scale="1 1 1"/>
      </geometry>
      <material name="lightgrey"/>
    </visual>
    <collision>
      <geometry>
        <mesh filename="package://darwin_description/meshes/shoulder_l_coll.stl" scale="1 1 1"/>
      </geometry>
    </collision>
  </link>
  <link name="MP_ARM_HIGH_L">
    <inertial>
      <origin xyz="-0.03432212 0.00089505 -0.00216268"/>
      <mass value="0.16837715"/>
      <inertia ixx="4.896e-05" ixy="2.7e-07" ixz="-3.93e-06" iyy="0.00013742" iyz="3.5e-07" izz="0.00012682"/>
    </inertial>
    <visual>
      <origin xyz="0 0 0" rpy="0 0 0"/>
      <geometry>
        <mesh filename="package://darwin_description/meshes/arm_high_l.STL" scale="1 1 1"/>
      </geometry>
      <material name="Grey">
        <color rgba="0.20 0.20 0.20 1.0"/>
      </material>
    </visual>
    <collision>
      <geometry>
        <mesh filename="package://darwin_description/meshes/arm_high_l_coll.stl" scale="1 1 1"/>
      </geometry>
    </collision>
  </link>
  <link name="MP_ARM_LOW_L">
    <inertial>
      <origin xyz="0.046 0.016 0.0"/>
      <mass value="0.0592885"/>
      <inertia ixx="1.111e-05" ixy="0.0" ixz="0.0" iyy="1.111e-05" iyz="0.0" izz="1.012e-05"/>
    </inertial>
    <visual>
      <origin xyz="0.016 0.016 0" rpy="0 0 0"/>
      <geometry>
        <box size="0.032 0.032 0.035"/>
      </geometry>
      <material name="black"/>
    </visual>
    <collision>
      <origin xyz="0.016 0.016 0" rpy="0 0 0"/>
      <geometry>
        <box size="0.032 0.032 0.035"/>
      </geometry>
    </collision>
  </link>
  <link name="MP_ARM_GRIPPER_FIX_L">
    <inertial>
      <origin xyz="0.01353588 -0.00168308 -0.0"/>
      <mass value="0.01"/>
      <inertia ixx="1.67e-06" ixy="5.9e-07" ixz="-0.0" iyy="6.39e-06" iyz="-0.0" izz="6.35e-06"/>
    </inertial>
    <visual>
      <origin xyz="0 0 0" rpy="0 0 0"/>
      <geometry>
        <mesh filename="package://darwin_description/meshes/arm_basic_low_l.stl" scale="1 1 1"/>
      </geometry>
      <material name="Grey">
        <color rgba="0.20 0.20 0.20 1.0"/>
      </material>
    </visual>
    <collision>
      <geometry>
        <mesh filename="package://darwin_description/meshes/arm_basic_low_l.stl" scale="1 1 1"/>
      </geometry>
    </collision>
  </link>
  <link name="MP_BACK_R">
    <inertial>
      <origin xyz="0.0 0.0 0.0"/>
      <mass value="0.01"/>
      <inertia ixx="0.0" ixy="0.0" ixz="0.0" iyy="0.0" iyz="0.0" izz="0.0"/>
    </inertial>
    <visual>
      <origin xyz="0.0 0.0 0.0" rpy="0 0 0"/>
      <geometry>
        <box size="0.001 0.001 0.001"/>
      </geometry>
      <material name="Grey">
        <color rgba="0.20 0.20 0.20 1.0"/>
      </material>
    </visual>
    <collision>
      <geometry>
        <box size="0.001 0.001 0.001"/>
      </geometry>
    </collision>
  </link>
  <link name="MP_SHOULDER_R">
    <inertial>
      <origin xyz="0.00578109 2.23e-06 0.01384056"/>
      <mass value="0.02591302"/>
      <inertia ixx="6.01e-06" ixy="-0.0" ixz="7.3e-07" iyy="3.72e-06" iyz="0.0" izz="6.37e-06"/>
    </inertial>
    <visual>
      <origin xyz="0 0 0" rpy="0 0 3.14"/>
      <geometry>
        <mesh filename="package://darwin_description/meshes/shoulder_r.STL" scale="1 1 1"/>
      </geometry>
      <material name="lightgrey"/>
    </visual>
    <collision>
      <origin xyz="0 0 0" rpy="0 0 3.14"/>
      <geometry>
        <mesh filename="package://darwin_description/meshes/shoulder_r_coll.stl" scale="1 1 1"/>
      </geometry>
    </collision>
  </link>
  <link name="MP_ARM_HIGH_R">
    <inertial>
      <origin xyz="-0.03432871 -0.00089179 -0.00217792"/>
      <mass value="0.16837715"/>
      <inertia ixx="4.894e-05" ixy="-2.5e-07" ixz="-3.89e-06" iyy="0.0001374" iyz="-3.3e-07" izz="0.0001269"/>
    </inertial>
    <visual>
      <origin xyz="0 0 0" rpy="3.14 0 0"/>
      <geometry>
        <mesh filename="package://darwin_description/meshes/arm_high_r.STL" scale="1 1 1"/>
      </geometry>
      <material name="Grey">
        <color rgba="0.20 0.20 0.20 1.0"/>
      </material>
    </visual>
    <collision>
      <geometry>
        <mesh filename="package://darwin_description/meshes/arm_high_r_coll.stl" scale="1 1 1"/>
      </geometry>
    </collision>
  </link>
  <link name="MP_ARM_LOW_R">
    <inertial>
      <origin xyz="0.0465 -0.016 0.0"/>
      <mass value="0.0592885"/>
      <inertia ixx="1.111e-05" ixy="0.0" ixz="0.0" iyy="1.111e-05" iyz="0.0" izz="1.012e-05"/>
    </inertial>
    <visual>
      <origin xyz="0.016 -0.016 0" rpy="0 0 0"/>
      <geometry>
        <box size="0.032 0.032 0.035"/>
      </geometry>
      <material name="black"/>
    </visual>
    <collision>
      <origin xyz="0.016 -0.016 0" rpy="0 0 0"/>
      <geometry>
        <box size="0.032 0.032 0.035"/>
      </geometry>
    </collision>
  </link>
  <link name="MP_ARM_GRIPPER_FIX_R">
    <inertial>
      <origin xyz="0.01353588 -0.00168308 -0.0"/>
      <mass value="0.01"/>
      <inertia ixx="1.67e-06" ixy="5.9e-07" ixz="-0.0" iyy="6.39e-06" iyz="-0.0" izz="6.35e-06"/>
    </inertial>
    <visual>
      <origin xyz="0 0 0" rpy="0 0 0"/>
      <geometry>
        <mesh filename="package://darwin_description/meshes/arm_basic_low_r.stl" scale="1 1 1"/>
      </geometry>
      <material name="Grey">
        <color rgba="0.20 0.20 0.20 1.0"/>
      </material>
    </visual>
    <collision>
      <geometry>
        <mesh filename="package://darwin_description/meshes/arm_basic_low_r.stl" scale="1 1 1"/>
      </geometry>
    </collision>
  </link>
  <link name="MP_PELVIS_L">
    <inertial>
      <origin xyz="-3.6e-06 0.00274563 0.01637871"/>
      <mass value="0.167108"/>
      <inertia ixx="5.095e-05" ixy="1e-08" ixz="1e-08" iyy="2.431e-05" iyz="1e-08" izz="4.36e-05"/>
    </inertial>
    <visual>
      <origin xyz="0 0 0" rpy="0 0 0"/>
      <geometry>
        <mesh filename="package://darwin_description/meshes/pelvis_l.STL" scale="1 1 1"/>
      </geometry>
      <material name="lightgrey"/>
    </visual>
    <collision>
      <geometry>
        <mesh filename="package://darwin_description/meshes/pelvis_l_coll.stl" scale="1 1 1"/>
      </geometry>
    </collision>
  </link>
  <link name="MP_THIGH1_L">
    <inertial>
      <origin xyz="-0.00055621 0.01256061 0.02010951"/>
      <mass value="0.11904336"/>
      <inertia ixx="8.564e-05" ixy="-3.8e-07" ixz="-5.2e-07" iyy="7.507e-05" iyz="-1.29e-06" izz="3.728e-05"/>
    </inertial>
    <visual>
      <origin xyz="0 0 0" rpy="0 0 0"/>
      <geometry>
        <mesh filename="package://darwin_description/meshes/thigh1_l.STL" scale="1 1 1"/>
      </geometry>
      <material name="black"/>
    </visual>
    <collision>
      <geometry>
        <mesh filename="package://darwin_description/meshes/thigh1_l_coll.stl" scale="1 1 1"/>
      </geometry>
    </collision>
  </link>
  <link name="MP_THIGH2_L">
    <inertial>
      <origin xyz="-0.0505506 -0.00237527 4.59e-06"/>
      <mass value="0.11904336"/>
      <inertia ixx="4.092e-05" ixy="3.5e-07" ixz="-2e-08" iyy="0.0001417" iyz="-1e-08" izz="0.00012927"/>
    </inertial>
    <visual>
      <origin xyz="0 0 0" rpy="0 0 0"/>
      <geometry>
        <mesh filename="package://darwin_description/meshes/thigh2_l.STL" scale="1 1 1"/>
      </geometry>
      <material name="Grey">
        <color rgba="0.20 0.20 0.20 1.0"/>
      </material>
    </visual>
    <collision>
      <geometry>
        <mesh filename="package://darwin_description/meshes/thigh2_l_coll.stl" scale="1 1 1"/>
      </geometry>
    </collision>
  </link>
  <link name="MP_TIBIA_L">
    <inertial>
      <origin xyz="-0.04465502 0.00065808 1.657e-05"/>
      <mass value="0.07030979"/>
      <inertia ixx="3.952e-05" ixy="1.132e-05" ixz="-4e-08" iyy="8.428e-05" iyz="-2e-08" izz="8.337e-05"/>
    </inertial>
    <visual>
      <origin xyz="0 0 0" rpy="0 0 0"/>
      <geometry>
        <mesh filename="package://darwin_description/meshes/tibia_l.STL" scale="1 1 1"/>
      </geometry>
      <material name="Grey">
        <color rgba="0.20 0.20 0.20 1.0"/>
      </material>
    </visual>
    <collision>
      <geometry>
        <mesh filename="package://darwin_description/meshes/tibia_l_coll.stl" scale="1 1 1"/>
      </geometry>
    </collision>
  </link>
  <link name="MP_ANKLE1_L">
    <inertial>
      <origin xyz="0.01267911 -0.02011283 -0.00055849"/>
      <mass value="0.16710792"/>
      <inertia ixx="0.00010548" ixy="2.15e-06" ixz="-5.2e-07" iyy="5.228e-05" iyz="5.9e-07" izz="0.00012021"/>
    </inertial>
    <visual>
      <origin xyz="0 0 0" rpy="0 0 0"/>
      <geometry>
        <mesh filename="package://darwin_description/meshes/ankle1_l.STL" scale="1 1 1"/>
      </geometry>
      <material name="black"/>
    </visual>
    <collision>
      <geometry>
        <mesh filename="package://darwin_description/meshes/ankle1_l_coll.stl" scale="1 1 1"/>
      </geometry>
    </collision>
  </link>
  <link name="MP_ANKLE2_L">
    <inertial>
      <origin xyz="-0.02659859 -0.0106184 -0.00243412"/>
      <mass value="0.0794462"/>
      <inertia ixx="9.461e-05" ixy="7e-08" ixz="1.07e-06" iyy="6.786e-05" iyz="6e-08" izz="2.933e-05"/>
    </inertial>
    <visual>
      <origin xyz="0 0 0" rpy="0 0 0"/>
      <geometry>
        <mesh filename="package://darwin_description/meshes/ankle2_l.STL" scale="1 1 1"/>
      </geometry>
      <material name="Grey">
        <color rgba="0.20 0.20 0.20 1.0"/>
      </material>
    </visual>
    <collision>
      <geometry>
        <mesh filename="package://darwin_description/meshes/ankle2_l_coll.stl" scale="1 1 1"/>
      </geometry>
    </collision>
  </link>
  <link name="MP_PELVIS_R">
    <inertial>
      <origin xyz="3.59e-06 -0.00274568 0.01637869"/>
      <mass value="0.167108"/>
      <inertia ixx="5.095e-05" ixy="1e-08" ixz="-1e-08" iyy="2.431e-05" iyz="-1e-08" izz="4.361e-05"/>
    </inertial>
    <visual>
      <origin xyz="0 0 0" rpy="0 0 0"/>
      <geometry>
        <mesh filename="package://darwin_description/meshes/pelvis_r.STL" scale="1 1 1"/>
      </geometry>
      <material name="lightgrey"/>
    </visual>
    <collision>
      <geometry>
        <mesh filename="package://darwin_description/meshes/pelvis_r_coll.stl" scale="1 1 1"/>
      </geometry>
    </collision>
  </link>
  <link name="MP_THIGH1_R">
    <inertial>
      <origin xyz="-0.00056702 -0.01268458 0.02009548"/>
      <mass value="0.11904336"/>
      <inertia ixx="8.559e-05" ixy="3.6e-07" ixz="-4.1e-07" iyy="7.506e-05" iyz="1.52e-06" izz="3.723e-05"/>
    </inertial>
    <visual>
      <origin xyz="0 0 0" rpy="0 0 0"/>
      <geometry>
        <mesh filename="package://darwin_description/meshes/thigh1_r.STL" scale="1 1 1"/>
      </geometry>
      <material name="black"/>
    </visual>
    <collision>
      <geometry>
        <mesh filename="package://darwin_description/meshes/thigh1_r_coll.stl" scale="1 1 1"/>
      </geometry>
    </collision>
  </link>
  <link name="MP_THIGH2_R">
    <inertial>
      <origin xyz="0.05054363 -0.00238112 -5.74e-06"/>
      <mass value="0.11904336"/>
      <inertia ixx="4.092e-05" ixy="-3.3e-07" ixz="-2e-08" iyy="0.00014167" iyz="0.0" izz="0.00012925"/>
    </inertial>
    <visual>
      <origin xyz="0 0 0" rpy="0 0 0"/>
      <geometry>
        <mesh filename="package://darwin_description/meshes/thigh2_r.STL" scale="1 1 1"/>
      </geometry>
      <material name="Grey">
        <color rgba="0.20 0.20 0.20 1.0"/>
      </material>
    </visual>
    <collision>
      <geometry>
        <mesh filename="package://darwin_description/meshes/thigh2_r_coll.stl" scale="1 1 1"/>
      </geometry>
    </collision>
  </link>
  <link name="MP_TIBIA_R">
    <inertial>
      <origin xyz="0.04470297 0.00064823 -1.647e-05"/>
      <mass value="0.07030979"/>
      <inertia ixx="3.954e-05" ixy="-1.134e-05" ixz="-3e-08" iyy="8.405e-05" iyz="3e-08" izz="8.317e-05"/>
    </inertial>
    <visual>
      <origin xyz="0 0 0" rpy="0 0 0"/>
      <geometry>
        <mesh filename="package://darwin_description/meshes/tibia_r.STL" scale="1 1 1"/>
      </geometry>
      <material name="Grey">
        <color rgba="0.20 0.20 0.20 1.0"/>
      </material>
    </visual>
    <collision>
      <geometry>
        <mesh filename="package://darwin_description/meshes/tibia_r_coll.stl" scale="1 1 1"/>
      </geometry>
    </collision>
  </link>
  <link name="MP_ANKLE1_R">
    <inertial>
      <origin xyz="-0.01254859 -0.02009754 -0.00055246"/>
      <mass value="0.16710792"/>
      <inertia ixx="0.00010546" ixy="-1.82e-06" ixz="5.3e-07" iyy="5.235e-05" iyz="5.9e-07" izz="0.00012028"/>
    </inertial>
    <visual>
      <origin xyz="0 0 0" rpy="0 0 0"/>
      <geometry>
        <mesh filename="package://darwin_description/meshes/ankle1_r.STL" scale="1 1 1"/>
      </geometry>
      <material name="black"/>
    </visual>
    <collision>
      <geometry>
        <mesh filename="package://darwin_description/meshes/ankle1_r_coll.stl" scale="1 1 1"/>
      </geometry>
    </collision>
  </link>
  <link name="MP_ANKLE2_R">
    <inertial>
      <origin xyz="0.02659998 -0.01061509 -0.00243811"/>
      <mass value="0.0794462"/>
      <inertia ixx="9.46e-05" ixy="-6e-08" ixz="-1.07e-06" iyy="6.785e-05" iyz="5e-08" izz="2.933e-05"/>
    </inertial>
    <visual>
      <origin xyz="0 0 0" rpy="0 0 0"/>
      <geometry>
        <mesh filename="package://darwin_description/meshes/ankle2_r.STL" scale="1 1 1"/>
      </geometry>
      <material name="Grey">
        <color rgba="0.20 0.20 0.20 1.0"/>
      </material>
    </visual>
    <collision>
      <geometry>
        <mesh filename="package://darwin_description/meshes/ankle2_r_coll.stl" scale="1 1 1"/>
      </geometry>
    </collision>
  </link>
  <link name="MP_PMDCAMBOARD">
    <!--
    <visual>
      <origin xyz="0 0 0" rpy="0 0 0" />
      <geometry>
        <box size="0.032 0.005 0.032" />
      </geometry>
      <material name="Grey">
        <color rgba="0.20 0.20 0.20 1.0"/>
      </material>
    </visual>
    -->
  </link>
  <joint name="j_camboard" type="fixed">
    <parent link="MP_HEAD"/>
    <child link="MP_PMDCAMBOARD"/>
    <origin xyz="0 0 0.0235" rpy="3.14159 1.5707963 0"/>
    <axis xyz="0 0 1"/>
    <limit effort="2.8" velocity="5.6548668" lower="-2.6179939" upper="2.6179939"/>
  </joint>
  <joint name="head_pan" type="revolute">
    <parent link="MP_BODY"/>
    <child link="MP_NECK"/>
    <origin xyz="0 0 0.0235" rpy="0 0 1.5707963"/>
    <axis xyz="0 0 1"/>
    <limit effort="2.8" velocity="5.6548668" lower="-2.6179939" upper="2.6179939"/>
  </joint>
  <joint name="head_tilt" type="revolute">
    <parent link="MP_NECK"/>
    <child link="MP_HEAD"/>
    <origin xyz="0 0 0.02715" rpy="-1.5707963 0 1.5707963"/>
    <axis xyz="0 0 1"/>
    <limit effort="2.8" velocity="5.6548668" lower="-1.0471976" upper="0.5235988"/>
  </joint>
  <joint name="j_back_l" type="fixed">
    <parent link="MP_BODY"/>
    <child link="MP_BACK_L"/>
    <origin xyz="0 0.06035 0" rpy="-1.5707963 0 0"/>
    <limit effort="2.8" velocity="5.6548668" lower="-2.6179939" upper="2.6179939"/>
  </joint>
  <joint name="l_sho_pitch" type="revolute">
    <parent link="MP_BACK_L"/>
    <child link="MP_SHOULDER_L"/>
    <origin xyz="0 0 0" rpy="0 0 -1.5707963"/>
    <axis xyz="0 0 1"/>
    <limit effort="2.8" velocity="5.6548668" lower="-4.3633231" upper="4.3633231"/>
  </joint>
  <joint name="l_sho_roll" type="revolute">
    <parent link="MP_SHOULDER_L"/>
    <child link="MP_ARM_HIGH_L"/>
    <origin xyz="-0.016 0 0.02165" rpy="1.5707963 1.5707963 0"/>
    <axis xyz="0 0 1"/>
    <limit effort="2.8" velocity="5.648668" lower="-1.7453293" upper="1.7453293"/>
  </joint>
  <joint name="l_el" type="revolute">
    <parent link="MP_ARM_HIGH_L"/>
    <child link="MP_ARM_LOW_L"/>
    <origin xyz="-0.06 0 -0.016" rpy="-1.5707963 3.14159 0"/>
    <axis xyz="0 0 1"/>
    <limit effort="2.8" velocity="5.6548668" lower="-2.7925268" upper="0"/>
  </joint>
  <joint name="j_wrist_l" type="fixed">
    <parent link="MP_ARM_LOW_L"/>
    <child link="MP_ARM_GRIPPER_FIX_L"/>
    <origin xyz="0.048 0.016 0" rpy="1.5707963 0 0"/>
    <axis xyz="0 0 1"/>
    <limit effort="2.8" velocity="5.6548668" lower="-2.6179939" upper="2.6179939"/>
  </joint>
  <joint name="j_back_r" type="fixed">
    <parent link="MP_BODY"/>
    <child link="MP_BACK_R"/>
    <origin xyz="0 -0.06035 0" rpy="1.5707963 0 0"/>
    <limit effort="2.8" velocity="5.6548668" lower="-2.6179939" upper="2.6179939"/>
  </joint>
  <joint name="r_sho_pitch" type="revolute">
    <parent link="MP_BACK_R"/>
    <child link="MP_SHOULDER_R"/>
    <origin xyz="0 0 0" rpy="0 0 -1.5707963"/>
    <axis xyz="0 0 1"/>
    <limit effort="2.8" velocity="5.6548668" lower="-4.3633231" upper="4.3633231"/>
  </joint>
  <joint name="r_sho_roll" type="revolute">
    <parent link="MP_SHOULDER_R"/>
    <child link="MP_ARM_HIGH_R"/>
    <origin xyz="0.016 0 0.02165" rpy="-1.5707963 1.5707963 0"/>
    <axis xyz="0 0 1"/>
    <limit effort="2.8" velocity="5.648668" lower="-1.7453293" upper="1.7453293"/>
  </joint>
  <joint name="r_el" type="revolute">
    <parent link="MP_ARM_HIGH_R"/>
    <child link="MP_ARM_LOW_R"/>
    <origin xyz="-0.06 0 0.016" rpy="-1.5707963 3.14159 0"/>
    <axis xyz="0 0 1"/>
    <limit effort="2.8" velocity="5.6548668" lower="0" upper="2.7925268"/>
  </joint>
  <joint name="j_wrist_r" type="fixed">
    <parent link="MP_ARM_LOW_R"/>
    <child link="MP_ARM_GRIPPER_FIX_R"/>
    <origin xyz="0.048 -0.016 0" rpy="1.5707963 0 0"/>
    <axis xyz="0 0 1"/>
    <limit effort="2.8" velocity="5.6548668" lower="-2.6179939" upper="2.6179939"/>
  </joint>
  <joint name="l_hip_yaw" type="revolute">
    <parent link="MP_BODY"/>
    <child link="MP_PELVIS_L"/>
    <origin xyz="-0.005 0.037 -0.09355" rpy="0 3.14159 -1.5707963"/>
    <axis xyz="0 0 1"/>
    <dynamics damping="0.1" friction="0.01"/>
    <limit effort="10" velocity="5.6548668" lower="-0.7853982" upper="2.6179939"/>
  </joint>
  <joint name="l_hip_roll" type="revolute">
    <parent link="MP_PELVIS_L"/>
    <child link="MP_THIGH1_L"/>
    <origin xyz="0 0 0.028652" rpy="1.5707963 0 0"/>
    <axis xyz="0 0 1"/>
    <dynamics damping="0.1" friction="0.01"/>
    <limit effort="10" velocity="5.6548668" lower="-1.0471976" upper="0"/>
  </joint>
  <joint name="l_hip_pitch" type="revolute">
    <parent link="MP_THIGH1_L"/>
    <child link="MP_THIGH2_L"/>
    <origin xyz="0 0 0" rpy="1.5707963 0 -1.5707963"/>
    <axis xyz="0 0 1"/>
    <dynamics damping="0.1" friction="0.01"/>
    <limit effort="10" velocity="5.6548668" lower="-0.5235988" upper="1.7453293"/>
  </joint>
  <joint name="l_knee" type="revolute">
    <parent link="MP_THIGH2_L"/>
    <child link="MP_TIBIA_L"/>
    <origin xyz="-0.093 0 0" rpy="0 0 0"/>
    <axis xyz="0 0 1"/>
    <dynamics damping="0.1" friction="0.01"/>
    <limit effort="10" velocity="5.6548668" lower="-2.268928" upper="0"/>
  </joint>
  <joint name="l_ank_pitch" type="revolute">
    <parent link="MP_TIBIA_L"/>
    <child link="MP_ANKLE1_L"/>
    <origin xyz="-0.093 0 0" rpy="3.14159 0 0"/>
    <axis xyz="0 0 1"/>
    <dynamics damping="0.1" friction="0.01"/>
    <limit effort="10" velocity="5.6548668" lower="-1.0471976" upper="1.0471976"/>
  </joint>
  <joint name="l_ank_roll" type="revolute">
    <parent link="MP_ANKLE1_L"/>
    <child link="MP_ANKLE2_L"/>
    <origin xyz="0 0 0" rpy="-1.5707963 0 0"/>
    <axis xyz="0 0 1"/>
    <dynamics damping="0.1" friction="0.01"/>
    <limit effort="10" velocity="5.6548668" lower="-0.5235988" upper="1.0471976"/>
  </joint>
  <joint name="r_hip_yaw" type="revolute">
    <parent link="MP_BODY"/>
    <child link="MP_PELVIS_R"/>
    <origin xyz="-0.005 -0.037 -0.09355" rpy="0 3.14159 1.5707963"/>
    <axis xyz="0 0 1"/>
    <dynamics damping="0.1" friction="0.01"/>
    <limit effort="10" velocity="5.6548668" lower="-2.6179939" upper="0.7853982"/>
  </joint>
  <joint name="r_hip_roll" type="revolute">
    <parent link="MP_PELVIS_R"/>
    <child link="MP_THIGH1_R"/>
    <origin xyz="0 0 0.028652" rpy="-1.5707963 0 0"/>
    <axis xyz="0 0 1"/>
    <dynamics damping="0.1" friction="0.01"/>
    <limit effort="10" velocity="5.6548668" lower="0" upper="1.0471976"/>
  </joint>
  <joint name="r_hip_pitch" type="revolute">
    <parent link="MP_THIGH1_R"/>
    <child link="MP_THIGH2_R"/>
    <origin xyz="0 0 0" rpy="1.5707963 0 -1.5707963"/>
    <axis xyz="0 0 1"/>
    <dynamics damping="0.1" friction="0.01"/>
    <limit effort="10" velocity="5.6548668" lower="-1.7453293" upper="0.5235988"/>
  </joint>
  <joint name="r_knee" type="revolute">
    <parent link="MP_THIGH2_R"/>
    <child link="MP_TIBIA_R"/>
    <origin xyz="0.093 0 0" rpy="0 0 0"/>
    <axis xyz="0 0 1"/>
    <dynamics damping="0.1" friction="0.01"/>
    <limit effort="10" velocity="5.6548668" lower="0" upper="2.268928"/>
  </joint>
  <joint name="r_ank_pitch" type="revolute">
    <parent link="MP_TIBIA_R"/>
    <child link="MP_ANKLE1_R"/>
    <origin xyz="0.093 0 0" rpy="3.14159 0 0"/>
    <axis xyz="0 0 1"/>
    <dynamics damping="0.1" friction="0.01"/>
    <limit effort="10" velocity="5.6548668" lower="-1.0471976" upper="1.0471976"/>
  </joint>
  <joint name="r_ank_roll" type="revolute">
    <parent link="MP_ANKLE1_R"/>
    <child link="MP_ANKLE2_R"/>
    <origin xyz="0 0 0" rpy="-1.5707963 0 0"/>
    <axis xyz="0 0 1"/>
    <dynamics damping="0.1" friction="0.01"/>
    <limit effort="10" velocity="5.6548668" lower="-0.5235988" upper="1.0471976"/>
  </joint>
  <gazebo>
    <plugin filename="libgazebo_ros_control.so" name="gazebo_ros_control">
      <robotNamespace>/darwin</robotNamespace>
    </plugin>
  </gazebo>
  <transmission name="t_head_pan">
    <type>transmission_interface/SimpleTransmission</type>
    <joint name="head_pan">
      <hardwareInterface>hardware_interface/EffortJointInterface</hardwareInterface>
    </joint>
    <actuator name="m_head_pan">
      <hardwareInterface>hardware_interface/EffortJointInterface</hardwareInterface>
      <mechanicalReduction>1</mechanicalReduction>
    </actuator>
  </transmission>
  <transmission name="t_head_tilt">
    <type>transmission_interface/SimpleTransmission</type>
    <joint name="head_tilt">
      <hardwareInterface>hardware_interface/EffortJointInterface</hardwareInterface>
    </joint>
    <actuator name="m_head_tilt">
      <hardwareInterface>hardware_interface/EffortJointInterface</hardwareInterface>
      <mechanicalReduction>1</mechanicalReduction>
    </actuator>
  </transmission>
  <transmission name="t_l_sho_pitch">
    <type>transmission_interface/SimpleTransmission</type>
    <joint name="l_sho_pitch">
      <hardwareInterface>hardware_interface/EffortJointInterface</hardwareInterface>
    </joint>
    <actuator name="m_l_sho_pitch">
      <hardwareInterface>hardware_interface/EffortJointInterface</hardwareInterface>
      <mechanicalReduction>1</mechanicalReduction>
    </actuator>
  </transmission>
  <transmission name="t_l_sho_roll">
    <type>transmission_interface/SimpleTransmission</type>
    <joint name="l_sho_roll">
      <hardwareInterface>hardware_interface/EffortJointInterface</hardwareInterface>
    </joint>
    <actuator name="m_l_sho_roll">
      <hardwareInterface>hardware_interface/EffortJointInterface</hardwareInterface>
      <mechanicalReduction>1</mechanicalReduction>
    </actuator>
  </transmission>
  <transmission name="t_l_el">
    <type>transmission_interface/SimpleTransmission</type>
    <joint name="l_el">
      <hardwareInterface>hardware_interface/EffortJointInterface</hardwareInterface>
    </joint>
    <actuator name="m_l_el">
      <hardwareInterface>hardware_interface/EffortJointInterface</hardwareInterface>
      <mechanicalReduction>1</mechanicalReduction>
    </actuator>
  </transmission>
  <transmission name="t_r_sho_pitch">
    <type>transmission_interface/SimpleTransmission</type>
    <joint name="r_sho_pitch">
      <hardwareInterface>hardware_interface/EffortJointInterface</hardwareInterface>
    </joint>
    <actuator name="m_r_sho_pitch">
      <hardwareInterface>hardware_interface/EffortJointInterface</hardwareInterface>
      <mechanicalReduction>1</mechanicalReduction>
    </actuator>
  </transmission>
  <transmission name="t_r_sho_roll">
    <type>transmission_interface/SimpleTransmission</type>
    <joint name="r_sho_roll">
      <hardwareInterface>hardware_interface/EffortJointInterface</hardwareInterface>
    </joint>
    <actuator name="m_r_sho_roll">
      <hardwareInterface>hardware_interface/EffortJointInterface</hardwareInterface>
      <mechanicalReduction>1</mechanicalReduction>
    </actuator>
  </transmission>
  <transmission name="t_r_el">
    <type>transmission_interface/SimpleTransmission</type>
    <joint name="r_el">
      <hardwareInterface>hardware_interface/EffortJointInterface</hardwareInterface>
    </joint>
    <actuator name="m_r_el">
      <hardwareInterface>hardware_interface/EffortJointInterface</hardwareInterface>
      <mechanicalReduction>1</mechanicalReduction>
    </actuator>
  </transmission>
  <transmission name="t_l_hip_yaw">
    <type>transmission_interface/SimpleTransmission</type>
    <joint name="l_hip_yaw">
      <hardwareInterface>hardware_interface/EffortJointInterface</hardwareInterface>
    </joint>
    <actuator name="m_l_hip_yaw">
      <hardwareInterface>hardware_interface/EffortJointInterface</hardwareInterface>
      <mechanicalReduction>1</mechanicalReduction>
    </actuator>
  </transmission>
  <transmission name="t_l_hip_roll">
    <type>transmission_interface/SimpleTransmission</type>
    <joint name="l_hip_roll">
      <hardwareInterface>hardware_interface/EffortJointInterface</hardwareInterface>
    </joint>
    <actuator name="m_l_hip_roll">
      <hardwareInterface>hardware_interface/EffortJointInterface</hardwareInterface>
      <mechanicalReduction>1</mechanicalReduction>
    </actuator>
  </transmission>
  <transmission name="t_l_hip_pitch">
    <type>transmission_interface/SimpleTransmission</type>
    <joint name="l_hip_pitch">
      <hardwareInterface>hardware_interface/EffortJointInterface</hardwareInterface>
    </joint>
    <actuator name="m_l_hip_pitch">
      <hardwareInterface>hardware_interface/EffortJointInterface</hardwareInterface>
      <mechanicalReduction>1</mechanicalReduction>
    </actuator>
  </transmission>
  <transmission name="t_l_knee">
    <type>transmission_interface/SimpleTransmission</type>
    <joint name="l_knee">
      <hardwareInterface>hardware_interface/EffortJointInterface</hardwareInterface>
    </joint>
    <actuator name="m_l_knee">
      <hardwareInterface>hardware_interface/EffortJointInterface</hardwareInterface>
      <mechanicalReduction>1</mechanicalReduction>
    </actuator>
  </transmission>
  <transmission name="t_l_ank_pitch">
    <type>transmission_interface/SimpleTransmission</type>
    <joint name="l_ank_pitch">
      <hardwareInterface>hardware_interface/EffortJointInterface</hardwareInterface>
    </joint>
    <actuator name="m_l_ank_pitch">
      <hardwareInterface>hardware_interface/EffortJointInterface</hardwareInterface>
      <mechanicalReduction>1</mechanicalReduction>
    </actuator>
  </transmission>
  <transmission name="t_l_ank_roll">
    <type>transmission_interface/SimpleTransmission</type>
    <joint name="l_ank_roll">
      <hardwareInterface>hardware_interface/EffortJointInterface</hardwareInterface>
    </joint>
    <actuator name="m_l_ank_roll">
      <hardwareInterface>hardware_interface/EffortJointInterface</hardwareInterface>
      <mechanicalReduction>1</mechanicalReduction>
    </actuator>
  </transmission>
  <transmission name="t_r_hip_yaw">
    <type>transmission_interface/SimpleTransmission</type>
    <joint name="r_hip_yaw">
      <hardwareInterface>hardware_interface/EffortJointInterface</hardwareInterface>
    </joint>
    <actuator name="m_r_hip_yaw">
      <hardwareInterface>hardware_interface/EffortJointInterface</hardwareInterface>
      <mechanicalReduction>1</mechanicalReduction>
    </actuator>
  </transmission>
  <transmission name="t_r_hip_roll">
    <type>transmission_interface/SimpleTransmission</type>
    <joint name="r_hip_roll">
      <hardwareInterface>hardware_interface/EffortJointInterface</hardwareInterface>
    </joint>
    <actuator name="m_r_hip_roll">
      <hardwareInterface>EffortJointInterface</hardwareInterface>
      <mechanicalReduction>1</mechanicalReduction>
    </actuator>
  </transmission>
  <transmission name="t_r_hip_pitch">
    <type>transmission_interface/SimpleTransmission</type>
    <joint name="r_hip_pitch">
      <hardwareInterface>hardware_interface/EffortJointInterface</hardwareInterface>
    </joint>
    <actuator name="m_r_hip_pitch">
      <hardwareInterface>hardware_interface/EffortJointInterface</hardwareInterface>
      <mechanicalReduction>1</mechanicalReduction>
    </actuator>
  </transmission>
  <transmission name="t_r_knee">
    <type>transmission_interface/SimpleTransmission</type>
    <joint name="r_knee">
      <hardwareInterface>hardware_interface/EffortJointInterface</hardwareInterface>
    </joint>
    <actuator name="m_r_knee">
      <hardwareInterface>hardware_interface/EffortJointInterface</hardwareInterface>
      <mechanicalReduction>1</mechanicalReduction>
    </actuator>
  </transmission>
  <transmission name="t_r_ank_pitch">
    <type>transmission_interface/SimpleTransmission</type>
    <joint name="r_ank_pitch">
      <hardwareInterface>hardware_interface/EffortJointInterface</hardwareInterface>
    </joint>
    <actuator name="m_r_ank_pitch">
      <hardwareInterface>hardware_interface/EffortJointInterface</hardwareInterface>
      <mechanicalReduction>1</mechanicalReduction>
    </actuator>
  </transmission>
  <transmission name="t_r_ank_roll">
    <type>transmission_interface/SimpleTransmission</type>
    <joint name="r_ank_roll">
      <hardwareInterface>hardware_interface/EffortJointInterface</hardwareInterface>
    </joint>
    <actuator name="m_r_ank_roll">
      <hardwareInterface>hardware_interface/EffortJointInterface</hardwareInterface>
      <mechanicalReduction>1</mechanicalReduction>
    </actuator>
  </transmission>
  <gazebo reference="MP_BODY">
    <material>Gazebo/Grey</material>
  </gazebo>
  <gazebo reference="MP_NECK">
    <material>Gazebo/White</material>
  </gazebo>
  <gazebo reference="MP_HEAD">
    <material>Gazebo/Grey</material>
  </gazebo>
  <gazebo reference="MP_BACK_L">
    <material>Gazebo/Grey</material>
  </gazebo>
  <gazebo reference="MP_SHOULDER_L">
    <material>Gazebo/White</material>
  </gazebo>
  <gazebo reference="MP_ARM_HIGH_L">
    <material>Gazebo/Grey</material>
  </gazebo>
  <gazebo reference="MP_ARM_LOW_L">
    <material>Gazebo/Black</material>
  </gazebo>
  <gazebo reference="MP_ARM_GRIPPER_FIX_L">
    <material>Gazebo/Grey</material>
  </gazebo>
  <gazebo reference="MP_BACK_R">
    <material>Gazebo/Grey</material>
  </gazebo>
  <gazebo reference="MP_SHOULDER_R">
    <material>Gazebo/White</material>
  </gazebo>
  <gazebo reference="MP_ARM_HIGH_R">
    <material>Gazebo/Grey</material>
  </gazebo>
  <gazebo reference="MP_ARM_LOW_R">
    <material>Gazebo/Black</material>
  </gazebo>
  <gazebo reference="MP_ARM_GRIPPER_FIX_R">
    <material>Gazebo/Grey</material>
  </gazebo>
  <gazebo reference="MP_PELVIS_L">
    <material>Gazebo/White</material>
  </gazebo>
  <gazebo reference="MP_THIGH1_L">
    <material>Gazebo/Black</material>
  </gazebo>
  <gazebo reference="MP_THIGH2_L">
    <material>Gazebo/Grey</material>
  </gazebo>
  <gazebo reference="MP_TIBIA_L">
    <material>Gazebo/Grey</material>
  </gazebo>
  <gazebo reference="MP_ANKLE1_L">
    <material>Gazebo/Black</material>
  </gazebo>
  <gazebo reference="MP_ANKLE2_L">
    <material>Gazebo/Grey</material>
    <mu1>9000</mu1>
    <mu2>9000</mu2>
    <kp>1000000.0</kp>
    <kd>1000.0</kd>
    <maxVel>0.0</maxVel>
    <minDepth>0.001</minDepth>
    <maxContacts>100</maxContacts>
  </gazebo>
  <gazebo reference="MP_PELVIS_R">
    <material>Gazebo/White</material>
  </gazebo>
  <gazebo reference="MP_THIGH1_R">
    <material>Gazebo/Black</material>
  </gazebo>
  <gazebo reference="MP_THIGH2_R">
    <material>Gazebo/Grey</material>
  </gazebo>
  <gazebo reference="MP_TIBIA_R">
    <material>Gazebo/Grey</material>
  </gazebo>
  <gazebo reference="MP_ANKLE1_R">
    <material>Gazebo/Black</material>
  </gazebo>
  <gazebo reference="MP_ANKLE2_R">
    <material>Gazebo/Grey</material>
    <mu1>9000</mu1>
    <mu2>9000</mu2>
    <kp>1000000.0</kp>
    <kd>1000.0</kd>
    <maxVel>0.0</maxVel>
    <minDepth>0.001</minDepth>
    <maxContacts>100</maxContacts>
  </gazebo>
  <gazebo reference="MP_PMDCAMBOARD">
    <material>Gazebo/Grey</material>
  </gazebo>
  <gazebo reference="">
    <material>Gazebo/Grey</material>
  </gazebo>
  <gazebo reference="MP_HEAD">
    <sensor name="camera" type="camera">
      <pose>-0.050000 -0.010000 0.000000 -1.5708 0.000000 -3.141592</pose>
      <camera name="__default__">
        <horizontal_fov>1.012300</horizontal_fov>
        <image>
          <width>320</width>
          <height>200</height>
        </image>
        <clip>
          <near>0.001000</near>
          <far>100.000000</far>
        </clip>
      </camera>
      <always_on>1</always_on>
      <update_rate>30.000000</update_rate>
      <visualize>1</visualize>
      <plugin name="camera_controller" filename="libgazebo_ros_camera.so">
        <alwaysOn>true</alwaysOn>
        <updateRate>30</updateRate>
        <cameraName>darwin/camera</cameraName>
        <imageTopicName>image_raw</imageTopicName>
        <cameraInfoTopicName>camera_info</cameraInfoTopicName>
        <frameName>MP_PMDCAMBOARD</frameName>
        <hackBaseline>0.07</hackBaseline>
        <distortionK1>0.0</distortionK1>
        <distortionK2>0.0</distortionK2>
        <distortionK3>0.0</distortionK3>
        <distortionT1>0.0</distortionT1>
        <distortionT2>0.0</distortionT2>
      </plugin>
    </sensor>
  </gazebo>
  <gazebo>
    <plugin filename="libhector_gazebo_ros_imu.so" name="gazebo_ros_imu">
      <bodyName>MP_BODY</bodyName>
      <updateRate>50</updateRate>
      <serviceName>/darwin/imu_service</serviceName>
      <topicName>/darwin/imu</topicName>
      <gaussianNoise>0</gaussianNoise>
      <xyzOffset>0 0 0</xyzOffset>
      <rpyOffset>0 0 -0.703220730592</rpyOffset>
    </plugin>
  </gazebo>
</robot>
